Workbook

Sheet Provinsi
A1: Kode | B1: Provinsi | C1: ADHB | Q1: ADHK | AE1: Distribusi | AS1: Q-to-Q | BG1: Y-on-Y | BU1: C-to-C | CI1: Implisit Q-to-Q | CW1: Implisit Y-on-Y
C2: PDRB | E2: PKRT | G2: PKLNPRT | I2: PKP | K2: PMTB | M2: PI | O2: Net Ekspor | Q2: PDRB | S2: PKRT | U2: PKLNPRT | W2: PKP | Y2: PMTB | AA2: PI | AC2: Net Ekspor | AE2: PDRB | AG2: PKRT | AI2: PKLNPRT | AK2: PKP | AM2: PMTB | AO2: PI | AQ2: Net Ekspor | AS2: PDRB | AU2: PKRT | AW2: PKLNPRT | AY2: PKP | BA2: PMTB | BC2: PI | BE2: Net Ekspor | BG2: PDRB | BI2: PKRT | BK2: PKLNPRT | BM2: PKP | BO2: PMTB | BQ2: PI | BS2: Net Ekspor | BU2: PDRB | BW2: PKRT | BY2: PKLNPRT | CA2: PKP | CC2: PMTB | CE2: PI | CG2: Net Ekspor | CI2: PDRB | CK2: PKRT | CM2: PKLNPRT | CO2: PKP | CQ2: PMTB | CS2: PI | CU2: Net Ekspor | CW2: PDRB | CY2: PKRT | DA2: PKLNPRT | DC2: PKP | DE2: PMTB | DG2: PI | DI2: Net Ekspor
C3: Q1-25 | D3: Q2-25 | E3: Q1-25 | F3: Q2-25 | G3: Q1-25 | H3: Q2-25 | I3: Q1-25 | J3: Q2-25 | K3: Q1-25 | L3: Q2-25 | M3: Q1-25 | N3: Q2-25 | O3: Q1-25 | P3: Q2-25 | Q3: Q1-25 | R3: Q2-25 | S3: Q1-25 | T3: Q2-25 | U3: Q1-25 | V3: Q2-25 | W3: Q1-25 | X3: Q2-25 | Y3: Q1-25 | Z3: Q2-25 | AA3: Q1-25 | AB3: Q2-25 | AC3: Q1-25 | AD3: Q2-25 | AE3: Q1-25 | AF3: Q2-25 | AG3: Q1-25 | AH3: Q2-25 | AI3: Q1-25 | AJ3: Q2-25 | AK3: Q1-25 | AL3: Q2-25 | AM3: Q1-25 | AN3: Q2-25 | AO3: Q1-25 | AP3: Q2-25 | AQ3: Q1-25 | AR3: Q2-25 | AS3: Q1-25 | AT3: Q2-25 | AU3: Q1-25 | AV3: Q2-25 | AW3: Q1-25 | AX3: Q2-25 | AY3: Q1-25 | AZ3: Q2-25 | BA3: Q1-25 | BB3: Q2-25 | BC3: Q1-25 | BD3: Q2-25 | BE3: Q1-25 | BF3: Q2-25 | BG3: Q1-25 | BH3: Q2-25 | BI3: Q1-25 | BJ3: Q2-25 | BK3: Q1-25 | BL3: Q2-25 | BM3: Q1-25 | BN3: Q2-25 | BO3: Q1-25 | BP3: Q2-25 | BQ3: Q1-25 | BR3: Q2-25 | BS3: Q1-25 | BT3: Q2-25 | BU3: Q1-25 | BV3: Q2-25 | BW3: Q1-25 | BX3: Q2-25 | BY3: Q1-25 | BZ3: Q2-25 | CA3: Q1-25 | CB3: Q2-25 | CC3: Q1-25 | CD3: Q2-25 | CE3: Q1-25 | CF3: Q2-25 | CG3: Q1-25 | CH3: Q2-25 | CI3: Q1-25 | CJ3: Q2-25 | CK3: Q1-25 | CL3: Q2-25 | CM3: Q1-25 | CN3: Q2-25 | CO3: Q1-25 | CP3: Q2-25 | CQ3: Q1-25 | CR3: Q2-25 | CS3: Q1-25 | CT3: Q2-25 | CU3: Q1-25 | CV3: Q2-25 | CW3: Q1-25 | CX3: Q2-25 | CY3: Q1-25 | CZ3: Q2-25 | DA3: Q1-25 | DB3: Q2-25 | DC3: Q1-25 | DD3: Q2-25 | DE3: Q1-25 | DF3: Q2-25 | DG3: Q1-25 | DH3: Q2-25 | DI3: Q1-25 | DJ3: Q2-25
A4: 11 | B4: Aceh | C4: ='[1]201'!B6 -> 61746996 | D4: ='[1]201'!C6 -> 63840334 | E4: ='[1]201'!B59 -> 34000224 | F4: ='[1]201'!C59 -> 35267596 | G4: ='[1]201'!B483 -> 1316016.7 | H4: ='[1]201'!C483 -> 1355213 | I4: ='[1]201'!B536 -> 7903443.6 | J4: ='[1]201'!C536 -> 10401852 | K4: ='[1]201'!B695 -> 18639452 | L4: ='[1]201'!C695 -> 19613396 | M4: ='[1]201'!B854 -> 1230191.7 | N4: ='[1]201'!C854 -> 116965.11 | O4: =C4-(E4+G4+I4+K4+M4) -> -1342332.5 | P4: =D4-(F4+H4+J4+L4+N4) -> -2914688.4 | Q4: ='[1]202'!B6 -> 38383878 | R4: ='[1]202'!C6 -> 39541324 | S4: ='[1]202'!B59 -> 21406190 | T4: ='[1]202'!C59 -> 21860454 | U4: ='[1]202'!B483 -> 860677.38 | V4: ='[1]202'!C483 -> 868323.07 | W4: ='[1]202'!B536 -> 4482516.2 | X4: ='[1]202'!C536 -> 5764377.4 | Y4: ='[1]202'!B695 -> 11569571 | Z4: ='[1]202'!C695 -> 12222589 | AA4: ='[1]202'!B854 -> 667240.98 | AB4: ='[1]202'!C854 -> 62648.887 | AC4: =Q4-(S4+U4+W4+Y4+AA4) -> -602317.46 | AD4: =R4-(T4+V4+X4+Z4+AB4) -> -1237068.1 | AE4: ='[1]205'!B6 -> 100 | AF4: ='[1]205'!C6 -> 100 | AG4: ='[1]205'!B59 -> 55.063771 | AH4: ='[1]205'!C59 -> 55.243439 | AI4: ='[1]205'!B483 -> 2.1313048 | AJ4: ='[1]205'!C483 -> 2.1228163 | AK4: ='[1]205'!B536 -> 12.799722 | AL4: ='[1]205'!C536 -> 16.293543 | AM4: ='[1]205'!B695 -> 30.186816 | AN4: ='[1]205'!C695 -> 30.722577 | AO4: ='[1]205'!B854 -> 1.9923102 | AP4: ='[1]205'!C854 -> 0.18321507 | AQ4: =AE4-(AG4+AI4+AK4+AM4+AO4) -> -2.1739235 | AR4: =AF4-(AH4+AJ4+AL4+AN4+AP4) -> -4.5655908 | AS4: ='[1]209'!B6 -> -6.0477047 | AT4: ='[1]209'!C6 -> 3.0154483 | AU4: ='[1]209'!B59 -> 2.4517454 | AV4: ='[1]209'!C59 -> 2.1221148 | AW4: ='[1]209'!B483 -> -2.9870263 | AX4: ='[1]209'!C483 -> 0.88833381 | AY4: ='[1]209'!B536 -> -44.683324 | AZ4: ='[1]209'!C536 -> 28.596911 | BA4: ='[1]209'!B695 -> -11.642041 | BB4: ='[1]209'!C695 -> 5.6442712 | BC4: - | BD4: - | BE4: - | BF4: - | BG4: ='[1]210'!B6 -> 4.5885778 | BH4: ='[1]210'!C6 -> 4.8153667 | BI4: ='[1]210'!B59 -> 4.9901099 | BJ4: ='[1]210'!C59 -> 4.9672501 | BK4: ='[1]210'!B483 -> -1.0070853 | BL4: ='[1]210'!C483 -> 16.31714 | BM4: ='[1]210'!B536 -> 7.9919623 | BN4: ='[1]210'!C536 -> -9.4013912 | BO4: ='[1]210'!B695 -> -0.11450719 | BP4: ='[1]210'!C695 -> -2.1339915 | BQ4: - | BR4: - | BS4: - | BT4: - | BU4: ='[1]211'!B6 -> 4.5885778 | BV4: ='[1]211'!C6 -> 4.7035337 | BW4: ='[1]211'!B59 -> 4.9901099 | BX4: ='[1]211'!C59 -> 4.9785588 | BY4: ='[1]211'!B483 -> -1.0070853 | BZ4: ='[1]211'!C483 -> 6.9961282 | CA4: ='[1]211'!B536 -> 7.9919623 | CB4: ='[1]211'!C536 -> -2.5342911 | CC4: ='[1]211'!B695 -> -0.11450719 | CD4: ='[1]211'!C695 -> -1.1622646 | CE4: - | CF4: - | CG4: - | CH4: - | CI4: ='[1]212'!B6 -> 0.55262014 | CJ4: ='[1]212'!C6 -> 0.36376932 | CK4: ='[1]212'!B59 -> 1.0458502 | CL4: ='[1]212'!C59 -> 1.5720641 | CM4: ='[1]212'!B483 -> 0.58438585 | CN4: ='[1]212'!C483 -> 2.0716679 | CO4: ='[1]212'!B536 -> -0.53444097 | CP4: ='[1]212'!C536 -> 2.3443285 | CQ4: ='[1]212'!B695 -> 0.43812351 | CR4: ='[1]212'!C695 -> -0.39670309 | CS4: - | CT4: - | CU4: - | CV4: - | CW4: ='[1]213'!B6 -> 2.6338517 | CX4: ='[1]213'!C6 -> 2.6479411 | CY4: ='[1]213'!B59 -> 1.1816217 | CZ4: ='[1]213'!C59 -> 2.6511037 | DA4: ='[1]213'!B483 -> 0.96266137 | DB4: ='[1]213'!C483 -> 2.2546304 | DC4: ='[1]213'!B536 -> 0.63124047 | DD4: ='[1]213'!C536 -> 1.1166949 | DE4: ='[1]213'!B695 -> 2.4509118 | DF4: ='[1]213'!C695 -> 0.97611642 | DG4: - | DH4: - | DI4: - | DJ4: -
A5: 12 | B5: Sumatera Utara | C5: ='[1]201'!B7 -> 2.9649046e+08 | D5: ='[1]201'!C7 -> 3.0673878e+08 | E5: ='[1]201'!B60 -> 1.5219131e+08 | F5: ='[1]201'!C60 -> 1.5715308e+08 | G5: ='[1]201'!B484 -> 2638739.2 | H5: ='[1]201'!C484 -> 2726963.3 | I5: ='[1]201'!B537 -> 14899539 | J5: ='[1]201'!C537 -> 16559029 | K5: ='[1]201'!B696 -> 81058986 | L5: ='[1]201'!C696 -> 82003137 | M5: ='[1]201'!B855 -> -1611781.5 | N5: ='[1]201'!C855 -> 1983673.1 | O5: =C5-(E5+G5+I5+K5+M5) -> 47313663 | P5: =D5-(F5+H5+J5+L5+N5) -> 46312896 | Q5: ='[1]202'!B7 -> 1.5994795e+08 | R5: ='[1]202'!C7 -> 1.6469233e+08 | S5: ='[1]202'!B60 -> 81398944 | T5: ='[1]202'!C60 -> 83680889 | U5: ='[1]202'!B484 -> 1762239.4 | V5: ='[1]202'!C484 -> 1805515.2 | W5: ='[1]202'!B537 -> 8450336.6 | X5: ='[1]202'!C537 -> 9333036 | Y5: ='[1]202'!B696 -> 46338026 | Z5: ='[1]202'!C696 -> 46748873 | AA5: ='[1]202'!B855 -> -931781.49 | AB5: ='[1]202'!C855 -> 1138381.4 | AC5: =Q5-(S5+U5+W5+Y5+AA5) -> 22930185 | AD5: =R5-(T5+V5+X5+Z5+AB5) -> 21985631 | AE5: ='[1]205'!B7 -> 100 | AF5: ='[1]205'!C7 -> 100 | AG5: ='[1]205'!B60 -> 51.330931 | AH5: ='[1]205'!C60 -> 51.233523 | AI5: ='[1]205'!B484 -> 0.88999128 | AJ5: ='[1]205'!C484 -> 0.8890181 | AK5: ='[1]205'!B537 -> 5.0253013 | AL5: ='[1]205'!C537 -> 5.3984138 | AM5: ='[1]205'!B696 -> 27.339492 | AN5: ='[1]205'!C696 -> 26.733867 | AO5: ='[1]205'!B855 -> -0.54362002 | AP5: ='[1]205'!C855 -> 0.64669784 | AQ5: =AE5-(AG5+AI5+AK5+AM5+AO5) -> 15.957904 | AR5: =AF5-(AH5+AJ5+AL5+AN5+AP5) -> 15.098481 | AS5: ='[1]209'!B7 -> -0.992649 | AT5: ='[1]209'!C7 -> 2.9661996 | AU5: ='[1]209'!B60 -> 0.35271963 | AV5: ='[1]209'!C60 -> 2.8034076 | AW5: ='[1]209'!B484 -> -5.9728894 | AX5: ='[1]209'!C484 -> 2.4557291 | AY5: ='[1]209'!B537 -> -16.949921 | AZ5: ='[1]209'!C537 -> 10.445732 | BA5: ='[1]209'!B696 -> -6.8548822 | BB5: ='[1]209'!C696 -> 0.88663033 | BC5: - | BD5: - | BE5: - | BF5: - | BG5: ='[1]210'!B7 -> 4.6669518 | BH5: ='[1]210'!C7 -> 4.6891518 | BI5: ='[1]210'!B60 -> 5.2875448 | BJ5: ='[1]210'!C60 -> 4.9481332 | BK5: ='[1]210'!B484 -> -0.92070587 | BL5: ='[1]210'!C484 -> 6.3426796 | BM5: ='[1]210'!B537 -> 3.3859646 | BN5: ='[1]210'!C537 -> -4.761808 | BO5: ='[1]210'!B696 -> 1.2274376 | BP5: ='[1]210'!C696 -> 0.89621651 | BQ5: - | BR5: - | BS5: - | BT5: - | BU5: ='[1]211'!B7 -> 4.6669518 | BV5: ='[1]211'!C7 -> 4.6782128 | BW5: ='[1]211'!B60 -> 5.2875448 | BX5: ='[1]211'!C60 -> 5.1152192 | BY5: ='[1]211'!B484 -> -0.92070587 | BZ5: ='[1]211'!C484 -> 2.6265913 | CA5: ='[1]211'!B537 -> 3.3859646 | CB5: ='[1]211'!C537 -> -1.0564987 | CC5: ='[1]211'!B696 -> 1.2274376 | CD5: ='[1]211'!C696 -> 1.0608248 | CE5: - | CF5: - | CG5: - | CH5: - | CI5: ='[1]212'!B7 -> 1.2663792 | CJ5: ='[1]212'!C7 -> 0.47621907 | CK5: ='[1]212'!B60 -> 1.4824131 | CL5: ='[1]212'!C60 -> 0.44435495 | CM5: ='[1]212'!B484 -> 0.71787258 | CN5: ='[1]212'!C484 -> 0.86641058 | CO5: ='[1]212'!B537 -> 0.83338478 | CP5: ='[1]212'!C537 -> 0.62666834 | CQ5: ='[1]212'!B696 -> 1.1624381 | CR5: ='[1]212'!C696 -> 0.2756959 | CS5: - | CT5: - | CU5: - | CV5: - | CW5: ='[1]213'!B7 -> 3.5773077 | CX5: ='[1]213'!C7 -> 2.692595 | CY5: ='[1]213'!B60 -> 2.9021896 | CZ5: ='[1]213'!C60 -> 1.9875704 | DA5: ='[1]213'!B484 -> 2.0904745 | DB5: ='[1]213'!C484 -> 2.6330291 | DC5: ='[1]213'!B537 -> 1.5315265 | DD5: ='[1]213'!C537 -> 1.7864536 | DE5: ='[1]213'!B696 -> 1.2527006 | DF5: ='[1]213'!C696 -> 1.5129979 | DG5: - | DH5: - | DI5: - | DJ5: -
A6: 13 | B6: Sumatera Barat | C6: ='[1]201'!B8 -> 86159253 | D6: ='[1]201'!C8 -> 88259733 | E6: ='[1]201'!B61 -> 45257135 | F6: ='[1]201'!C61 -> 45525988 | G6: ='[1]201'!B485 -> 935970.85 | H6: ='[1]201'!C485 -> 954751.96 | I6: ='[1]201'!B538 -> 6302526.7 | J6: ='[1]201'!C538 -> 7793428.4 | K6: ='[1]201'!B697 -> 23541840 | L6: ='[1]201'!C697 -> 24633423 | M6: ='[1]201'!B856 -> 881688.45 | N6: ='[1]201'!C856 -> -47583.634 | O6: =C6-(E6+G6+I6+K6+M6) -> 9240092.3 | P6: =D6-(F6+H6+J6+L6+N6) -> 9399725.3 | Q6: ='[1]202'!B8 -> 50929223 | R6: ='[1]202'!C8 -> 51703523 | S6: ='[1]202'!B61 -> 24966251 | T6: ='[1]202'!C61 -> 24928126 | U6: ='[1]202'!B485 -> 587054.59 | V6: ='[1]202'!C485 -> 589207.94 | W6: ='[1]202'!B538 -> 3601416 | X6: ='[1]202'!C538 -> 4351945.2 | Y6: ='[1]202'!B697 -> 13254917 | Z6: ='[1]202'!C697 -> 13837809 | AA6: ='[1]202'!B856 -> 533469.55 | AB6: ='[1]202'!C856 -> -28745.441 | AC6: =Q6-(S6+U6+W6+Y6+AA6) -> 7986114.4 | AD6: =R6-(T6+V6+X6+Z6+AB6) -> 8025179.7 | AE6: ='[1]205'!B8 -> 100 | AF6: ='[1]205'!C8 -> 100 | AG6: ='[1]205'!B61 -> 52.527306 | AH6: ='[1]205'!C61 -> 51.581833 | AI6: ='[1]205'!B485 -> 1.0863266 | AJ6: ='[1]205'!C485 -> 1.0817526 | AK6: ='[1]205'!B538 -> 7.3149737 | AL6: ='[1]205'!C538 -> 8.8301064 | AM6: ='[1]205'!B697 -> 27.323635 | AN6: ='[1]205'!C697 -> 27.910149 | AO6: ='[1]205'!B856 -> 1.0233242 | AP6: ='[1]205'!C856 -> -0.053913186 | AQ6: =AE6-(AG6+AI6+AK6+AM6+AO6) -> 10.724434 | AR6: =AF6-(AH6+AJ6+AL6+AN6+AP6) -> 10.650072 | AS6: ='[1]209'!B8 -> -0.10731651 | AT6: ='[1]209'!C8 -> 1.5203452 | AU6: ='[1]209'!B61 -> 4.4581795 | AV6: ='[1]209'!C61 -> -0.15270646 | AW6: ='[1]209'!B485 -> 5.571449 | AX6: ='[1]209'!C485 -> 0.36680502 | AY6: ='[1]209'!B538 -> -32.938485 | AZ6: ='[1]209'!C538 -> 20.839838 | BA6: ='[1]209'!B697 -> -15.605827 | BB6: ='[1]209'!C697 -> 4.3975545 | BC6: - | BD6: - | BE6: - | BF6: - | BG6: ='[1]210'!B8 -> 4.5526008 | BH6: ='[1]210'!C8 -> 3.9428575 | BI6: ='[1]210'!B61 -> 4.0763556 | BJ6: ='[1]210'!C61 -> 0.94126597 | BK6: ='[1]210'!B485 -> -1.692579 | BL6: ='[1]210'!C485 -> 6.6447542 | BM6: ='[1]210'!B538 -> 5.907741 | BN6: ='[1]210'!C538 -> -2.1930112 | BO6: ='[1]210'!B697 -> -0.31266367 | BP6: ='[1]210'!C697 -> -0.26667178 | BQ6: - | BR6: - | BS6: - | BT6: - | BU6: ='[1]211'!B8 -> 4.5526008 | BV6: ='[1]211'!C8 -> 4.2445375 | BW6: ='[1]211'!B61 -> 4.0763556 | BX6: ='[1]211'!C61 -> 2.4860377 | BY6: ='[1]211'!B485 -> -1.692579 | BZ6: ='[1]211'!C485 -> 2.3141281 | CA6: ='[1]211'!B538 -> 5.907741 | CB6: ='[1]211'!C538 -> 1.316113 | CC6: ='[1]211'!B697 -> -0.31266367 | CD6: ='[1]211'!C697 -> -0.28917828 | CE6: - | CF6: - | CG6: - | CH6: - | CI6: ='[1]212'!B8 -> 0.96341062 | CJ6: ='[1]212'!C8 -> 0.90381826 | CK6: ='[1]212'!B61 -> 2.0387135 | CL6: ='[1]212'!C61 -> 0.74790665 | CM6: ='[1]212'!B485 -> 0.58694515 | CN6: ='[1]212'!C485 -> 1.6337939 | CO6: ='[1]212'!B538 -> -0.98277458 | CP6: ='[1]212'!C538 -> 2.3301762 | CQ6: ='[1]212'!B697 -> 3.8855841 | CR6: ='[1]212'!C697 -> 0.22914722 | CS6: - | CT6: - | CU6: - | CV6: - | CW6: ='[1]213'!B8 -> 2.1084969 | CX6: ='[1]213'!C8 -> 1.9521868 | CY6: ='[1]213'!B61 -> 1.5001175 | CZ6: ='[1]213'!C61 -> 1.0007163 | DA6: ='[1]213'!B485 -> 0.47833249 | DB6: ='[1]213'!C485 -> 1.2043967 | DC6: ='[1]213'!B538 -> -0.50419642 | DD6: ='[1]213'!C538 -> 1.7414874 | DE6: ='[1]213'!B697 -> 4.2193761 | DF6: ='[1]213'!C697 -> 4.3776027 | DG6: - | DH6: - | DI6: - | DJ6: -
A7: 14 | B7: Riau | C7: ='[1]201'!B9 -> 2.9341445e+08 | D7: ='[1]201'!C9 -> 2.9304813e+08 | E7: ='[1]201'!B62 -> 98235916 | F7: ='[1]201'!C62 -> 1.0312577e+08 | G7: ='[1]201'!B486 -> 1699086 | H7: ='[1]201'!C486 -> 1588996.5 | I7: ='[1]201'!B539 -> 8048949.2 | J7: ='[1]201'!C539 -> 8793380.1 | K7: ='[1]201'!B698 -> 88108719 | L7: ='[1]201'!C698 -> 90898321 | M7: ='[1]201'!B857 -> -1369162.1 | N7: ='[1]201'!C857 -> 2716592.6 | O7: =C7-(E7+G7+I7+K7+M7) -> 98690939 | P7: =D7-(F7+H7+J7+L7+N7) -> 85925066 | Q7: ='[1]202'!B9 -> 1.4533568e+08 | R7: ='[1]202'!C9 -> 1.4754576e+08 | S7: ='[1]202'!B62 -> 50384206 | T7: ='[1]202'!C62 -> 52715139 | U7: ='[1]202'!B486 -> 889879.06 | V7: ='[1]202'!C486 -> 819216.53 | W7: ='[1]202'!B539 -> 4461453.8 | X7: ='[1]202'!C539 -> 4834971.4 | Y7: ='[1]202'!B698 -> 43996999 | Z7: ='[1]202'!C698 -> 44983748 | AA7: ='[1]202'!B857 -> -684032.61 | AB7: ='[1]202'!C857 -> 1347853.9 | AC7: =Q7-(S7+U7+W7+Y7+AA7) -> 46287171 | AD7: =R7-(T7+V7+X7+Z7+AB7) -> 42844832 | AE7: ='[1]205'!B9 -> 100 | AF7: ='[1]205'!C9 -> 100 | AG7: ='[1]205'!B62 -> 33.480259 | AH7: ='[1]205'!C62 -> 35.190729 | AI7: ='[1]205'!B486 -> 0.57907375 | AJ7: ='[1]205'!C486 -> 0.54223055 | AK7: ='[1]205'!B539 -> 2.7432014 | AL7: ='[1]205'!C539 -> 3.0006607 | AM7: ='[1]205'!B698 -> 30.02876 | AN7: ='[1]205'!C698 -> 31.018222 | AO7: ='[1]205'!B857 -> -0.46663078 | AP7: ='[1]205'!C857 -> 0.92701244 | AQ7: =AE7-(AG7+AI7+AK7+AM7+AO7) -> 33.635337 | AR7: =AF7-(AH7+AJ7+AL7+AN7+AP7) -> 29.321145 | AS7: ='[1]209'!B9 -> -0.28985956 | AT7: ='[1]209'!C9 -> 1.5206757 | AU7: ='[1]209'!B62 -> -2.3779648 | AV7: ='[1]209'!C62 -> 4.6263172 | AW7: ='[1]209'!B486 -> 3.0206914 | AX7: ='[1]209'!C486 -> -7.9406891 | AY7: ='[1]209'!B539 -> -19.88103 | AZ7: ='[1]209'!C539 -> 8.3721041 | BA7: ='[1]209'!B698 -> 1.1357064 | BB7: ='[1]209'!C698 -> 2.2427646 | BC7: - | BD7: - | BE7: - | BF7: - | BG7: ='[1]210'!B9 -> 4.6523232 | BH7: ='[1]210'!C9 -> 4.5903549 | BI7: ='[1]210'!B62 -> 4.8555732 | BJ7: ='[1]210'!C62 -> 4.6911636 | BK7: ='[1]210'!B486 -> -1.2524 | BL7: ='[1]210'!C486 -> -0.75855 | BM7: ='[1]210'!B539 -> 4.0606381 | BN7: ='[1]210'!C539 -> -7.4111196 | BO7: ='[1]210'!B698 -> 1.1684259 | BP7: ='[1]210'!C698 -> 2.4739618 | BQ7: - | BR7: - | BS7: - | BT7: - | BU7: ='[1]211'!B9 -> 4.6523232 | BV7: ='[1]211'!C9 -> 4.6210961 | BW7: ='[1]211'!B62 -> 4.8555732 | BX7: ='[1]211'!C62 -> 4.7714454 | BY7: ='[1]211'!B486 -> -1.2524 | BZ7: ='[1]211'!C486 -> -1.0162989 | CA7: ='[1]211'!B539 -> 4.0606381 | CB7: ='[1]211'!C539 -> -2.2389877 | CC7: ='[1]211'!B698 -> 1.1684259 | CD7: ='[1]211'!C698 -> 1.8242481 | CE7: - | CF7: - | CG7: - | CH7: - | CI7: ='[1]212'!B9 -> 1.7358077 | CJ7: ='[1]212'!C9 -> -1.6208737 | CK7: ='[1]212'!B62 -> 1.7409699 | CL7: ='[1]212'!C62 -> 0.33581489 | CM7: ='[1]212'!B486 -> 0.66424364 | CN7: ='[1]212'!C486 -> 1.5874004 | CO7: ='[1]212'!B539 -> -0.5099722 | CP7: ='[1]212'!C539 -> 0.80896509 | CQ7: ='[1]212'!B698 -> -0.55403313 | CR7: ='[1]212'!C698 -> 0.90307241 | CS7: - | CT7: - | CU7: - | CV7: - | CW7: ='[1]213'!B9 -> 6.0831833 | CX7: ='[1]213'!C9 -> 2.1929331 | CY7: ='[1]213'!B62 -> 1.0442935 | CZ7: ='[1]213'!C62 -> 0.61619 | DA7: ='[1]213'!B486 -> 0.40804238 | DB7: ='[1]213'!C486 -> 1.546384 | DC7: ='[1]213'!B539 -> 0.71872937 | DD7: ='[1]213'!C539 -> 0.21617637 | DE7: ='[1]213'!B698 -> 0.43650256 | DF7: ='[1]213'!C698 -> 1.7548562 | DG7: - | DH7: - | DI7: - | DJ7: -
A8: 15 | B8: Jambi | C8: ='[1]201'!B10 -> 82259967 | D8: ='[1]201'!C10 -> 87253248 | E8: ='[1]201'!B63 -> 33955771 | F8: ='[1]201'!C63 -> 36623562 | G8: ='[1]201'!B487 -> 472401.07 | H8: ='[1]201'!C487 -> 516960.31 | I8: ='[1]201'!B540 -> 3528222 | J8: ='[1]201'!C540 -> 4901470.4 | K8: ='[1]201'!B699 -> 16597160 | L8: ='[1]201'!C699 -> 17686129 | M8: ='[1]201'!B858 -> -196409.95 | N8: ='[1]201'!C858 -> 656986.29 | O8: =C8-(E8+G8+I8+K8+M8) -> 27902822 | P8: =D8-(F8+H8+J8+L8+N8) -> 26868139 | Q8: ='[1]202'!B10 -> 43889840 | R8: ='[1]202'!C10 -> 46345712 | S8: ='[1]202'!B63 -> 19446514 | T8: ='[1]202'!C63 -> 20489190 | U8: ='[1]202'!B487 -> 270846.73 | V8: ='[1]202'!C487 -> 290924.98 | W8: ='[1]202'!B540 -> 1979104.5 | X8: ='[1]202'!C540 -> 2710091.2 | Y8: ='[1]202'!B699 -> 9945116.2 | Z8: ='[1]202'!C699 -> 10554806 | AA8: ='[1]202'!B858 -> -96096.033 | AB8: ='[1]202'!C858 -> 319120.88 | AC8: =Q8-(S8+U8+W8+Y8+AA8) -> 12344354 | AD8: =R8-(T8+V8+X8+Z8+AB8) -> 11981580 | AE8: ='[1]205'!B10 -> 100 | AF8: ='[1]205'!C10 -> 100 | AG8: ='[1]205'!B63 -> 41.278611 | AH8: ='[1]205'!C63 -> 41.973867 | AI8: ='[1]205'!B487 -> 0.57427821 | AJ8: ='[1]205'!C487 -> 0.5924826 | AK8: ='[1]205'!B540 -> 4.2891119 | AL8: ='[1]205'!C540 -> 5.617522 | AM8: ='[1]205'!B699 -> 20.176473 | AN8: ='[1]205'!C699 -> 20.269881 | AO8: ='[1]205'!B858 -> -0.23876736 | AP8: ='[1]205'!C858 -> 0.75296485 | AQ8: =AE8-(AG8+AI8+AK8+AM8+AO8) -> 33.920294 | AR8: =AF8-(AH8+AJ8+AL8+AN8+AP8) -> 30.793283 | AS8: ='[1]209'!B10 -> -3.7421511 | AT8: ='[1]209'!C10 -> 5.5955365 | AU8: ='[1]209'!B63 -> 0.51281772 | AV8: ='[1]209'!C63 -> 5.3617596 | AW8: ='[1]209'!B487 -> -6.8350149 | AX8: ='[1]209'!C487 -> 7.4131414 | AY8: ='[1]209'!B540 -> -46.226786 | AZ8: ='[1]209'!C540 -> 36.935223 | BA8: ='[1]209'!B699 -> -11.997279 | BB8: ='[1]209'!C699 -> 6.1305414 | BC8: - | BD8: - | BE8: - | BF8: - | BG8: ='[1]210'!B10 -> 4.5603432 | BH8: ='[1]210'!C10 -> 4.9948881 | BI8: ='[1]210'!B63 -> 4.8952143 | BJ8: ='[1]210'!C63 -> 4.8328387 | BK8: ='[1]210'!B487 -> -7.521918 | BL8: ='[1]210'!C487 -> 8.6525469 | BM8: ='[1]210'!B540 -> 3.2174081 | BN8: ='[1]210'!C540 -> -22.345892 | BO8: ='[1]210'!B699 -> 1.4367745 | BP8: ='[1]210'!C699 -> 3.2165472 | BQ8: - | BR8: - | BS8: - | BT8: - | BU8: ='[1]211'!B10 -> 4.5603432 | BV8: ='[1]211'!C10 -> 4.7830788 | BW8: ='[1]211'!B63 -> 4.8952143 | BX8: ='[1]211'!C63 -> 4.8632029 | BY8: ='[1]211'!B487 -> -7.521918 | BZ8: ='[1]211'!C487 -> 0.20296159 | CA8: ='[1]211'!B540 -> 3.2174081 | CB8: ='[1]211'!C540 -> -13.281327 | CC8: ='[1]211'!B699 -> 1.4367745 | CD8: ='[1]211'!C699 -> 2.3453929 | CE8: - | CF8: - | CG8: - | CH8: - | CI8: ='[1]212'!B10 -> 1.2989195 | CJ8: ='[1]212'!C10 -> 0.44943762 | CK8: ='[1]212'!B63 -> 0.57654885 | CL8: ='[1]212'!C63 -> 2.3679414 | CM8: ='[1]212'!B487 -> 0.21981473 | CN8: ='[1]212'!C487 -> 1.8799937 | CO8: ='[1]212'!B540 -> 0.6652152 | CP8: ='[1]212'!C540 -> 1.45076 | CQ8: ='[1]212'!B699 -> 0.31745616 | CR8: ='[1]212'!C699 -> 0.40576053 | CS8: - | CT8: - | CU8: - | CV8: - | CW8: ='[1]213'!B10 -> 5.537183 | CX8: ='[1]213'!C10 -> 2.4811336 | CY8: ='[1]213'!B63 -> -0.25466971 | CZ8: ='[1]213'!C63 -> 1.7759155 | DA8: ='[1]213'!B487 -> 0.16948621 | DB8: ='[1]213'!C487 -> 1.3812671 | DC8: ='[1]213'!B540 -> 1.1231772 | DD8: ='[1]213'!C540 -> 0.93150885 | DE8: ='[1]213'!B699 -> 1.5727401 | DF8: ='[1]213'!C699 -> 1.3560135 | DG8: - | DH8: - | DI8: - | DJ8: -
A9: 16 | B9: Sumatera Selatan | C9: ='[1]201'!B11 -> 1.7080845e+08 | D9: ='[1]201'!C11 -> 1.8044985e+08 | E9: ='[1]201'!B64 -> 1.0738898e+08 | F9: ='[1]201'!C64 -> 1.1132113e+08 | G9: ='[1]201'!B488 -> 2782936.6 | H9: ='[1]201'!C488 -> 3009943.1 | I9: ='[1]201'!B541 -> 8337197.8 | J9: ='[1]201'!C541 -> 10002364 | K9: ='[1]201'!B700 -> 51815809 | L9: ='[1]201'!C700 -> 53775936 | M9: ='[1]201'!B859 -> -5556.8895 | N9: ='[1]201'!C859 -> 3276.21 | O9: =C9-(E9+G9+I9+K9+M9) -> 489084.98 | P9: =D9-(F9+H9+J9+L9+N9) -> 2337197.4 | Q9: ='[1]202'!B11 -> 95769564 | R9: ='[1]202'!C11 -> 1.0022384e+08 | S9: ='[1]202'!B64 -> 56922389 | T9: ='[1]202'!C64 -> 58882057 | U9: ='[1]202'!B488 -> 1611796.5 | V9: ='[1]202'!C488 -> 1708100.4 | W9: ='[1]202'!B541 -> 4789608.7 | X9: ='[1]202'!C541 -> 5719132.1 | Y9: ='[1]202'!B700 -> 28922893 | Z9: ='[1]202'!C700 -> 29934772 | AA9: ='[1]202'!B859 -> -2704.37 | AB9: ='[1]202'!C859 -> 1591.54 | AC9: =Q9-(S9+U9+W9+Y9+AA9) -> 3525582.1 | AD9: =R9-(T9+V9+X9+Z9+AB9) -> 3978187.3 | AE9: ='[1]205'!B11 -> 100 | AF9: ='[1]205'!C11 -> 100 | AG9: ='[1]205'!B64 -> 62.870998 | AH9: ='[1]205'!C64 -> 61.690898 | AI9: ='[1]205'!B488 -> 1.6292734 | AJ9: ='[1]205'!C488 -> 1.668022 | AK9: ='[1]205'!B541 -> 4.8810219 | AL9: ='[1]205'!C541 -> 5.5430162 | AM9: ='[1]205'!B700 -> 30.335624 | AN9: ='[1]205'!C700 -> 29.801043 | AO9: ='[1]205'!B859 -> -0.0032532873 | AP9: ='[1]205'!C859 -> 0.0018155793 | AQ9: =AE9-(AG9+AI9+AK9+AM9+AO9) -> 0.28633536 | AR9: =AF9-(AH9+AJ9+AL9+AN9+AP9) -> 1.2952061 | AS9: ='[1]209'!B11 -> 0.16469193 | AT9: ='[1]209'!C11 -> 4.6510351 | AU9: ='[1]209'!B64 -> 0.59379156 | AV9: ='[1]209'!C64 -> 3.4427018 | AW9: ='[1]209'!B488 -> 4.9245136 | AX9: ='[1]209'!C488 -> 5.9749407 | AY9: ='[1]209'!B541 -> -38.341365 | AZ9: ='[1]209'!C541 -> 19.407083 | BA9: ='[1]209'!B700 -> -4.535615 | BB9: ='[1]209'!C700 -> 3.4985418 | BC9: - | BD9: - | BE9: - | BF9: - | BG9: ='[1]210'!B11 -> 5.2231764 | BH9: ='[1]210'!C11 -> 5.417332 | BI9: ='[1]210'!B64 -> 4.9061772 | BJ9: ='[1]210'!C64 -> 4.9255805 | BK9: ='[1]210'!B488 -> 1.2120149 | BL9: ='[1]210'!C488 -> 4.9880611 | BM9: ='[1]210'!B541 -> 4.9030283 | BN9: ='[1]210'!C541 -> -3.9798897 | BO9: ='[1]210'!B700 -> 2.2055286 | BP9: ='[1]210'!C700 -> 5.6538843 | BQ9: - | BR9: - | BS9: - | BT9: - | BU9: ='[1]211'!B11 -> 5.2231764 | BV9: ='[1]211'!C11 -> 5.322371 | BW9: ='[1]211'!B64 -> 4.9061772 | BX9: ='[1]211'!C64 -> 4.9160421 | BY9: ='[1]211'!B488 -> 1.2120149 | BZ9: ='[1]211'!C488 -> 3.1202422 | CA9: ='[1]211'!B541 -> 4.9030283 | CB9: ='[1]211'!C541 -> -0.12535249 | CC9: ='[1]211'!B700 -> 2.2055286 | CD9: ='[1]211'!C700 -> 3.9307449 | CE9: - | CF9: - | CG9: - | CH9: - | CI9: ='[1]212'!B11 -> 0.95038392 | CJ9: ='[1]212'!C11 -> 0.94937777 | CK9: ='[1]212'!B64 -> 1.7748626 | CL9: ='[1]212'!C64 -> 0.21161325 | CM9: ='[1]212'!B488 -> 0.40508345 | CN9: ='[1]212'!C488 -> 2.0591112 | CO9: ='[1]212'!B541 -> -1.7689323 | CP9: ='[1]212'!C541 -> 0.47371794 | CQ9: ='[1]212'!B700 -> 0.50704014 | CR9: ='[1]212'!C700 -> 0.27472087 | CS9: - | CT9: - | CU9: - | CV9: - | CW9: ='[1]213'!B11 -> 3.1189196 | CX9: ='[1]213'!C11 -> 3.1420334 | CY9: ='[1]213'!B64 -> 3.3478058 | CZ9: ='[1]213'!C64 -> 2.3842772 | DA9: ='[1]213'!B488 -> 2.6627835 | DB9: ='[1]213'!C488 -> 3.0964154 | DC9: ='[1]213'!B541 -> 8.4470423 | DD9: ='[1]213'!C541 -> 2.6623172 | DE9: ='[1]213'!B700 -> 1.322637 | DF9: ='[1]213'!C700 -> 1.2238112 | DG9: - | DH9: - | DI9: - | DJ9: -
A10: 17 | B10: Bengkulu | C10: ='[1]201'!B12 -> 26535907 | D10: ='[1]201'!C12 -> 28458231 | E10: ='[1]201'!B65 -> 15920505 | F10: ='[1]201'!C65 -> 17291985 | G10: ='[1]201'!B489 -> 654686.66 | H10: ='[1]201'!C489 -> 699229.67 | I10: ='[1]201'!B542 -> 4165955 | J10: ='[1]201'!C542 -> 4626876.5 | K10: ='[1]201'!B701 -> 9335280 | L10: ='[1]201'!C701 -> 10265407 | M10: ='[1]201'!B860 -> -11178.91 | N10: ='[1]201'!C860 -> 443483.66 | O10: =C10-(E10+G10+I10+K10+M10) -> -3529341.3 | P10: =D10-(F10+H10+J10+L10+N10) -> -4868750.6 | Q10: ='[1]202'!B12 -> 13654253 | R10: ='[1]202'!C12 -> 14602946 | S10: ='[1]202'!B65 -> 8981157.4 | T10: ='[1]202'!C65 -> 9619442.4 | U10: ='[1]202'!B489 -> 412033.98 | V10: ='[1]202'!C489 -> 430333.7 | W10: ='[1]202'!B542 -> 2316121.6 | X10: ='[1]202'!C542 -> 2611068 | Y10: ='[1]202'!B701 -> 5532824.1 | Z10: ='[1]202'!C701 -> 5766783 | AA10: ='[1]202'!B860 -> -9185.19 | AB10: ='[1]202'!C860 -> 351389.06 | AC10: =Q10-(S10+U10+W10+Y10+AA10) -> -3578698.8 | AD10: =R10-(T10+V10+X10+Z10+AB10) -> -4176069.7 | AE10: ='[1]205'!B12 -> 100 | AF10: ='[1]205'!C12 -> 100 | AG10: ='[1]205'!B65 -> 59.996086 | AH10: ='[1]205'!C65 -> 60.762684 | AI10: ='[1]205'!B489 -> 2.4671728 | AJ10: ='[1]205'!C489 -> 2.4570385 | AK10: ='[1]205'!B542 -> 15.699313 | AL10: ='[1]205'!C542 -> 16.258483 | AM10: ='[1]205'!B701 -> 35.179804 | AN10: ='[1]205'!C701 -> 36.071838 | AO10: ='[1]205'!B860 -> -0.042127484 | AP10: ='[1]205'!C860 -> 1.558367 | AQ10: =AE10-(AG10+AI10+AK10+AM10+AO10) -> -13.300248 | AR10: =AF10-(AH10+AJ10+AL10+AN10+AP10) -> -17.108409 | AS10: ='[1]209'!B12 -> -2.2730655 | AT10: ='[1]209'!C12 -> 6.9479692 | AU10: ='[1]209'!B65 -> -0.54256697 | AV10: ='[1]209'!C65 -> 7.1069348 | AW10: ='[1]209'!B489 -> 0.71 | AX10: ='[1]209'!C489 -> 4.4413135 | AY10: ='[1]209'!B542 -> -25.923361 | AZ10: ='[1]209'!C542 -> 12.734497 | BA10: ='[1]209'!B701 -> -9.0177319 | BB10: ='[1]209'!C701 -> 4.2285605 | BC10: - | BD10: - | BE10: - | BF10: - | BG10: ='[1]210'!B12 -> 4.8372093 | BH10: ='[1]210'!C12 -> 4.9943363 | BI10: ='[1]210'!B65 -> 5.592109 | BJ10: ='[1]210'!C65 -> 5.6517209 | BK10: ='[1]210'!B489 -> 3.2565284 | BL10: ='[1]210'!C489 -> 11.35 | BM10: ='[1]210'!B542 -> -0.6832954 | BN10: ='[1]210'!C542 -> -0.13517985 | BO10: ='[1]210'!B701 -> 1.3919874 | BP10: ='[1]210'!C701 -> 4.1876457 | BQ10: - | BR10: - | BS10: - | BT10: - | BU10: ='[1]211'!B12 -> 4.8372093 | BV10: ='[1]211'!C12 -> 4.9183517 | BW10: ='[1]211'!B65 -> 5.592109 | BX10: ='[1]211'!C65 -> 5.6229294 | BY10: ='[1]211'!B489 -> 3.2565284 | BZ10: ='[1]211'!C489 -> 7.2385082 | CA10: ='[1]211'!B542 -> -0.6832954 | CB10: ='[1]211'!C542 -> -0.39358384 | CC10: ='[1]211'!B701 -> 1.3919874 | CD10: ='[1]211'!C701 -> 2.7997525 | CE10: - | CF10: - | CG10: - | CH10: - | CI10: ='[1]212'!B12 -> 0.59340087 | CJ10: ='[1]212'!C12 -> 0.27701988 | CK10: ='[1]212'!B65 -> 0.71112528 | CL10: ='[1]212'!C65 -> 1.4075753 | CM10: ='[1]212'!B489 -> -1.0510608 | CN10: ='[1]212'!C489 -> 2.2619408 | CO10: ='[1]212'!B542 -> 3.3229435 | CP10: ='[1]212'!C542 -> -1.4817929 | CQ10: ='[1]212'!B701 -> -4.2227196 | CR10: ='[1]212'!C701 -> 5.5023358 | CS10: - | CT10: - | CU10: - | CV10: - | CW10: ='[1]213'!B12 -> 2.60399 | CX10: ='[1]213'!C12 -> 2.2768528 | CY10: ='[1]213'!B65 -> 0.31136382 | CZ10: ='[1]213'!C65 -> 0.94100357 | DA10: ='[1]213'!B489 -> -0.46 | DB10: ='[1]213'!C489 -> 0.34275007 | DC10: ='[1]213'!B542 -> 1.8271506 | DD10: ='[1]213'!C542 -> 1.8036858 | DE10: ='[1]213'!B701 -> 0.79372757 | DF10: ='[1]213'!C701 -> 1.477422 | DG10: - | DH10: - | DI10: - | DJ10: -
A11: 18 | B11: Lampung | C11: ='[1]201'!B13 -> 1.217066e+08 | D11: ='[1]201'!C13 -> 1.343956e+08 | E11: ='[1]201'!B66 -> 78851092 | F11: ='[1]201'!C66 -> 83874234 | G11: ='[1]201'!B490 -> 2276693.7 | H11: ='[1]201'!C490 -> 2373935.2 | I11: ='[1]201'!B543 -> 6402262.5 | J11: ='[1]201'!C543 -> 7615283.3 | K11: ='[1]201'!B702 -> 37145448 | L11: ='[1]201'!C702 -> 39268987 | M11: ='[1]201'!B861 -> 1097162.6 | N11: ='[1]201'!C861 -> 1090461.8 | O11: =C11-(E11+G11+I11+K11+M11) -> -4066057.8 | P11: =D11-(F11+H11+J11+L11+N11) -> 172694.45 | Q11: ='[1]202'!B13 -> 69559035 | R11: ='[1]202'!C13 -> 76047838 | S11: ='[1]202'!B66 -> 43361615 | T11: ='[1]202'!C66 -> 45522492 | U11: ='[1]202'!B490 -> 1201045.1 | V11: ='[1]202'!C490 -> 1230350.5 | W11: ='[1]202'!B543 -> 3645361.2 | X11: ='[1]202'!C543 -> 4252457.6 | Y11: ='[1]202'!B702 -> 21802872 | Z11: ='[1]202'!C702 -> 23010667 | AA11: ='[1]202'!B861 -> 497284.39 | AB11: ='[1]202'!C861 -> 493084.04 | AC11: =Q11-(S11+U11+W11+Y11+AA11) -> -949142.8 | AD11: =R11-(T11+V11+X11+Z11+AB11) -> 1538787 | AE11: ='[1]205'!B13 -> 100 | AF11: ='[1]205'!C13 -> 100 | AG11: ='[1]205'!B66 -> 64.787851 | AH11: ='[1]205'!C66 -> 62.40847 | AI11: ='[1]205'!B490 -> 1.8706411 | AJ11: ='[1]205'!C490 -> 1.7663787 | AK11: ='[1]205'!B543 -> 5.260407 | AL11: ='[1]205'!C543 -> 5.6663191 | AM11: ='[1]205'!B702 -> 30.520488 | AN11: ='[1]205'!C702 -> 29.218953 | AO11: ='[1]205'!B861 -> 0.90148156 | AP11: ='[1]205'!C861 -> 0.81138212 | AQ11: =AE11-(AG11+AI11+AK11+AM11+AO11) -> -3.3408687 | AR11: =AF11-(AH11+AJ11+AL11+AN11+AP11) -> 0.12849711 | AS11: ='[1]209'!B13 -> -1.1080083 | AT11: ='[1]209'!C13 -> 9.3284828 | AU11: ='[1]209'!B66 -> 0.59219605 | AV11: ='[1]209'!C66 -> 4.9833858 | AW11: ='[1]209'!B490 -> -1.87 | AX11: ='[1]209'!C490 -> 2.44 | AY11: ='[1]209'!B543 -> -39.784583 | AZ11: ='[1]209'!C543 -> 16.653945 | BA11: ='[1]209'!B702 -> -6.7499511 | BB11: ='[1]209'!C702 -> 5.5396126 | BC11: - | BD11: - | BE11: - | BF11: - | BG11: ='[1]210'!B13 -> 5.4662754 | BH11: ='[1]210'!C13 -> 5.0949089 | BI11: ='[1]210'!B66 -> 5.060163 | BJ11: ='[1]210'!C66 -> 4.6695808 | BK11: ='[1]210'!B490 -> 2.2989586 | BL11: ='[1]210'!C490 -> 4.6694498 | BM11: ='[1]210'!B543 -> -1.582 | BN11: ='[1]210'!C543 -> -2.1287198 | BO11: ='[1]210'!B702 -> 1.2554057 | BP11: ='[1]210'!C702 -> 5.3146064 | BQ11: - | BR11: - | BS11: - | BT11: - | BU11: ='[1]211'!B13 -> 5.4662754 | BV11: ='[1]211'!C13 -> 5.2719906 | BW11: ='[1]211'!B66 -> 5.060163 | BX11: ='[1]211'!C66 -> 4.8597607 | BY11: ='[1]211'!B490 -> 2.2989586 | BZ11: ='[1]211'!C490 -> 3.4849149 | CA11: ='[1]211'!B543 -> -1.582 | CB11: ='[1]211'!C543 -> -1.8771295 | CC11: ='[1]211'!B702 -> 1.2554057 | CD11: ='[1]211'!C702 -> 3.2998322 | CE11: - | CF11: - | CG11: - | CH11: - | CI11: ='[1]212'!B13 -> 1.2517225 | CJ11: ='[1]212'!C13 -> 1.00377 | CK11: ='[1]212'!B66 -> 0.8054282 | CL11: ='[1]212'!C66 -> 1.3211907 | CM11: ='[1]212'!B490 -> 0.65813069 | CN11: ='[1]212'!C490 -> 1.787556 | CO11: ='[1]212'!B543 -> 0.4123323 | CP11: ='[1]212'!C543 -> 1.965477 | CQ11: ='[1]212'!B702 -> -0.053957346 | CR11: ='[1]212'!C702 -> 0.16790676 | CS11: - | CT11: - | CU11: - | CV11: - | CW11: ='[1]213'!B13 -> 2.9490465 | CX11: ='[1]213'!C13 -> 2.5754299 | CY11: ='[1]213'!B66 -> 2.0059437 | CZ11: ='[1]213'!C66 -> 2.7575094 | DA11: ='[1]213'!B490 -> 1.5812104 | DB11: ='[1]213'!C490 -> 3.0056101 | DC11: ='[1]213'!B543 -> 1.9062073 | DD11: ='[1]213'!C543 -> 2.3870758 | DE11: ='[1]213'!B702 -> 1.5671039 | DF11: ='[1]213'!C702 -> 1.1313953 | DG11: - | DH11: - | DI11: - | DJ11: -
A12: 19 | B12: Kepulauan Bangka Belitung | C12: ='[1]201'!B14 -> 27416313 | D12: ='[1]201'!C14 -> 29263995 | E12: ='[1]201'!B67 -> 15473811 | F12: ='[1]201'!C67 -> 15830211 | G12: ='[1]201'!B491 -> 231438.27 | H12: ='[1]201'!C491 -> 236219.45 | I12: ='[1]201'!B544 -> 1897018.6 | J12: ='[1]201'!C544 -> 2473001.4 | K12: ='[1]201'!B703 -> 6398702.3 | L12: ='[1]201'!C703 -> 6589243.7 | M12: ='[1]201'!B862 -> 28933.376 | N12: ='[1]201'!C862 -> 30141.235 | O12: =C12-(E12+G12+I12+K12+M12) -> 3386409.7 | P12: =D12-(F12+H12+J12+L12+N12) -> 4105178.7 | Q12: ='[1]202'!B14 -> 15141499 | R12: ='[1]202'!C14 -> 15982308 | S12: ='[1]202'!B67 -> 8300018.8 | T12: ='[1]202'!C67 -> 8453828.7 | U12: ='[1]202'!B491 -> 120666.72 | V12: ='[1]202'!C491 -> 122137.3 | W12: ='[1]202'!B544 -> 1036398.9 | X12: ='[1]202'!C544 -> 1303537.1 | Y12: ='[1]202'!B703 -> 3047493.6 | Z12: ='[1]202'!C703 -> 3113473.7 | AA12: ='[1]202'!B862 -> 8310.3677 | AB12: ='[1]202'!C862 -> 8779.0744 | AC12: =Q12-(S12+U12+W12+Y12+AA12) -> 2628610.8 | AD12: =R12-(T12+V12+X12+Z12+AB12) -> 2980552.3 | AE12: ='[1]205'!B14 -> 100 | AF12: ='[1]205'!C14 -> 100 | AG12: ='[1]205'!B67 -> 56.44016 | AH12: ='[1]205'!C67 -> 54.094496 | AI12: ='[1]205'!B491 -> 0.84416262 | AJ12: ='[1]205'!C491 -> 0.80720164 | AK12: ='[1]205'!B544 -> 6.9193058 | AL12: ='[1]205'!C544 -> 8.4506622 | AM12: ='[1]205'!B703 -> 23.339033 | AN12: ='[1]205'!C703 -> 22.516555 | AO12: ='[1]205'!B862 -> 0.10553343 | AP12: ='[1]205'!C862 -> 0.10299768 | AQ12: =AE12-(AG12+AI12+AK12+AM12+AO12) -> 12.351806 | AR12: =AF12-(AH12+AJ12+AL12+AN12+AP12) -> 14.028087 | AS12: ='[1]209'!B14 -> -3.8726072 | AT12: ='[1]209'!C14 -> 5.5530095 | AU12: ='[1]209'!B67 -> 1.2382926 | AV12: ='[1]209'!C67 -> 1.8531265 | AW12: ='[1]209'!B491 -> 0.66150145 | AX12: ='[1]209'!C491 -> 1.2187148 | AY12: ='[1]209'!B544 -> -43.430813 | AZ12: ='[1]209'!C544 -> 25.775611 | BA12: ='[1]209'!B703 -> -8.73791 | BB12: ='[1]209'!C703 -> 2.1650605 | BC12: - | BD12: - | BE12: - | BF12: - | BG12: ='[1]210'!B14 -> 4.598676 | BH12: ='[1]210'!C14 -> 4.0949779 | BI12: ='[1]210'!B67 -> 1.6922458 | BJ12: ='[1]210'!C67 -> 3.4484644 | BK12: ='[1]210'!B491 -> 3.3475533 | BL12: ='[1]210'!C491 -> 10.30014 | BM12: ='[1]210'!B544 -> -4.676362 | BN12: ='[1]210'!C544 -> -11.769172 | BO12: ='[1]210'!B703 -> -2.8496098 | BP12: ='[1]210'!C703 -> -1.8071788 | BQ12: - | BR12: - | BS12: - | BT12: - | BU12: ='[1]211'!B14 -> 4.598676 | BV12: ='[1]211'!C14 -> 4.3394159 | BW12: ='[1]211'!B67 -> 1.6922458 | BX12: ='[1]211'!C67 -> 2.5708992 | BY12: ='[1]211'!B491 -> 3.3475533 | BZ12: ='[1]211'!C491 -> 6.7317565 | CA12: ='[1]211'!B544 -> -4.676362 | CB12: ='[1]211'!C544 -> -8.7622993 | CC12: ='[1]211'!B703 -> -2.8496098 | CD12: ='[1]211'!C703 -> -2.3255937 | CE12: - | CF12: - | CG12: - | CH12: - | CI12: ='[1]212'!B14 -> 1.3048791 | CJ12: ='[1]212'!C14 -> 1.1239311 | CK12: ='[1]212'!B67 -> 1.5455131 | CL12: ='[1]212'!C67 -> 0.441929 | CM12: ='[1]212'!B491 -> 1.2217925 | CN12: ='[1]212'!C491 -> 0.83694173 | CO12: ='[1]212'!B544 -> -2.1331341 | CP12: ='[1]212'!C544 -> 3.6469057 | CQ12: ='[1]212'!B703 -> 0.019049209 | CR12: ='[1]212'!C703 -> 0.79552825 | CS12: - | CT12: - | CU12: - | CV12: - | CW12: ='[1]213'!B14 -> 4.042472 | CX12: ='[1]213'!C14 -> 3.7121238 | CY12: ='[1]213'!B67 -> 1.4244727 | CZ12: ='[1]213'!C67 -> 1.1404418 | DA12: ='[1]213'!B491 -> 3.8259682 | DB12: ='[1]213'!C491 -> 4.3143403 | DC12: ='[1]213'!B544 -> -1.6011445 | DD12: ='[1]213'!C544 -> 0.94005239 | DE12: ='[1]213'!B703 -> 3.6396152 | DF12: ='[1]213'!C703 -> 2.2810408 | DG12: - | DH12: - | DI12: - | DJ12: -
A13: 21 | B13: Kepulauan Riau | C13: ='[1]201'!B15 -> 91298693 | D13: ='[1]201'!C15 -> 93700807 | E13: ='[1]201'!B68 -> 38258667 | F13: ='[1]201'!C68 -> 39409438 | G13: ='[1]201'!B492 -> 230211.24 | H13: ='[1]201'!C492 -> 249330.53 | I13: ='[1]201'!B545 -> 3044105.8 | J13: ='[1]201'!C545 -> 3653000.4 | K13: ='[1]201'!B704 -> 39654378 | L13: ='[1]201'!C704 -> 41937741 | M13: ='[1]201'!B863 -> -643120.63 | N13: ='[1]201'!C863 -> 1178925.3 | O13: =C13-(E13+G13+I13+K13+M13) -> 10754452 | P13: =D13-(F13+H13+J13+L13+N13) -> 7272372.4 | Q13: ='[1]202'!B15 -> 53855962 | R13: ='[1]202'!C15 -> 55205871 | S13: ='[1]202'!B68 -> 20976528 | T13: ='[1]202'!C68 -> 21493800 | U13: ='[1]202'!B492 -> 121832.1 | V13: ='[1]202'!C492 -> 131338.64 | W13: ='[1]202'!B545 -> 1651413.7 | X13: ='[1]202'!C545 -> 1948067.1 | Y13: ='[1]202'!B704 -> 21750558 | Z13: ='[1]202'!C704 -> 22978578 | AA13: ='[1]202'!B863 -> -341903.44 | AB13: ='[1]202'!C863 -> 625279.09 | AC13: =Q13-(S13+U13+W13+Y13+AA13) -> 9697533.5 | AD13: =R13-(T13+V13+X13+Z13+AB13) -> 8028808.6 | AE13: ='[1]205'!B15 -> 100 | AF13: ='[1]205'!C15 -> 100 | AG13: ='[1]205'!B68 -> 41.904945 | AH13: ='[1]205'!C68 -> 42.058803 | AI13: ='[1]205'!B492 -> 0.25215174 | AJ13: ='[1]205'!C492 -> 0.26609219 | AK13: ='[1]205'!B545 -> 3.3342272 | AL13: ='[1]205'!C545 -> 3.8985795 | AM13: ='[1]205'!B704 -> 43.433675 | AN13: ='[1]205'!C704 -> 44.757076 | AO13: ='[1]205'!B863 -> -0.70441384 | AP13: ='[1]205'!C863 -> 1.2581805 | AQ13: =AE13-(AG13+AI13+AK13+AM13+AO13) -> 11.779415 | AR13: =AF13-(AH13+AJ13+AL13+AN13+AP13) -> 7.7612697 | AS13: ='[1]209'!B15 -> -2.7774016 | AT13: ='[1]209'!C15 -> 2.5065182 | AU13: ='[1]209'!B68 -> 0.67842549 | AV13: ='[1]209'!C68 -> 2.4659588 | AW13: ='[1]209'!B492 -> 1.4647992 | AX13: ='[1]209'!C492 -> 7.802984 | AY13: ='[1]209'!B545 -> -50.062687 | AZ13: ='[1]209'!C545 -> 17.963599 | BA13: ='[1]209'!B704 -> -4.9691453 | BB13: ='[1]209'!C704 -> 5.6459217 | BC13: - | BD13: - | BE13: - | BF13: - | BG13: ='[1]210'!B15 -> 5.1575949 | BH13: ='[1]210'!C15 -> 7.136161 | BI13: ='[1]210'!B68 -> 3.1484396 | BJ13: ='[1]210'!C68 -> 3.900706 | BK13: ='[1]210'!B492 -> -0.99436951 | BL13: ='[1]210'!C492 -> 9.7087591 | BM13: ='[1]210'!B545 -> 4.8564083 | BN13: ='[1]210'!C545 -> -15.322789 | BO13: ='[1]210'!B704 -> 3.2667008 | BP13: ='[1]210'!C704 -> 8.6981068 | BQ13: - | BR13: - | BS13: - | BT13: - | BU13: ='[1]211'!B15 -> 5.1575949 | BV13: ='[1]211'!C15 -> 6.1499031 | BW13: ='[1]211'!B68 -> 3.1484396 | BX13: ='[1]211'!C68 -> 3.5277875 | BY13: ='[1]211'!B492 -> -0.99436951 | BZ13: ='[1]211'!C492 -> 4.2835691 | CA13: ='[1]211'!B545 -> 4.8564083 | CB13: ='[1]211'!C545 -> -7.1223695 | CC13: ='[1]211'!B704 -> 3.2667008 | CD13: ='[1]211'!C704 -> 5.9873784 | CE13: - | CF13: - | CG13: - | CH13: - | CI13: ='[1]212'!B15 -> 0.4930262 | CJ13: ='[1]212'!C15 -> 0.12148652 | CK13: ='[1]212'!B68 -> 1.0780312 | CL13: ='[1]212'!C68 -> 0.52886751 | CM13: ='[1]212'!B492 -> 0.15155045 | CN13: ='[1]212'!C492 -> 0.46577647 | CO13: ='[1]212'!B545 -> -0.96167033 | CP13: ='[1]212'!C545 -> 1.7283409 | CQ13: ='[1]212'!B704 -> 0.52114178 | CR13: ='[1]212'!C704 -> 0.10624247 | CS13: - | CT13: - | CU13: - | CV13: - | CW13: ='[1]213'!B15 -> 1.5114037 | CX13: ='[1]213'!C15 -> 0.88201063 | CY13: ='[1]213'!B68 -> 2.2777399 | CZ13: ='[1]213'!C68 -> 2.2780278 | DA13: ='[1]213'!B492 -> 1.4350643 | DB13: ='[1]213'!C492 -> 1.1005074 | DC13: ='[1]213'!B545 -> 2.7010788 | DD13: ='[1]213'!C545 -> 3.0670819 | DE13: ='[1]213'!B704 -> 1.0938024 | DF13: ='[1]213'!C704 -> 0.88209877 | DG13: - | DH13: - | DI13: - | DJ13: -
A14: 31 | B14: Dki Jakarta | C14: ='[1]201'!B17 -> 9.574988e+08 | D14: ='[1]201'!C17 -> 9.7663019e+08 | E14: ='[1]201'!B70 -> 5.8910344e+08 | F14: ='[1]201'!C70 -> 6.2029857e+08 | G14: ='[1]201'!B494 -> 22008822 | H14: ='[1]201'!C494 -> 22787125 | I14: ='[1]201'!B547 -> 1.1540799e+08 | J14: ='[1]201'!C547 -> 1.1478846e+08 | K14: ='[1]201'!B706 -> 3.1112408e+08 | L14: ='[1]201'!C706 -> 3.2164192e+08 | M14: ='[1]201'!B865 -> 5509981.5 | N14: ='[1]201'!C865 -> 6401304.9 | O14: =C14-(E14+G14+I14+K14+M14) -> -85655514 | P14: =D14-(F14+H14+J14+L14+N14) -> -1.0928719e+08 | Q14: ='[1]202'!B17 -> 5.5424553e+08 | R14: ='[1]202'!C17 -> 5.6309396e+08 | S14: ='[1]202'!B70 -> 3.2215337e+08 | T14: ='[1]202'!C70 -> 3.333769e+08 | U14: ='[1]202'!B494 -> 13190941 | V14: ='[1]202'!C494 -> 13316213 | W14: ='[1]202'!B547 -> 62207209 | X14: ='[1]202'!C547 -> 60617144 | Y14: ='[1]202'!B706 -> 1.9785209e+08 | Z14: ='[1]202'!C706 -> 2.0423871e+08 | AA14: ='[1]202'!B865 -> 2209428.5 | AB14: ='[1]202'!C865 -> 2560795.7 | AC14: =Q14-(S14+U14+W14+Y14+AA14) -> -43367502 | AD14: =R14-(T14+V14+X14+Z14+AB14) -> -51015807 | AE14: ='[1]205'!B17 -> 100 | AF14: ='[1]205'!C17 -> 100 | AG14: ='[1]205'!B70 -> 61.52524 | AH14: ='[1]205'!C70 -> 63.514171 | AI14: ='[1]205'!B494 -> 2.2985744 | AJ14: ='[1]205'!C494 -> 2.3332399 | AK14: ='[1]205'!B547 -> 12.053069 | AL14: ='[1]205'!C547 -> 11.753524 | AM14: ='[1]205'!B706 -> 32.493417 | AN14: ='[1]205'!C706 -> 32.93385 | AO14: ='[1]205'!B865 -> 0.5754557 | AP14: ='[1]205'!C865 -> 0.65544819 | AQ14: =AE14-(AG14+AI14+AK14+AM14+AO14) -> -8.9457568 | AR14: =AF14-(AH14+AJ14+AL14+AN14+AP14) -> -11.190232 | AS14: ='[1]209'!B17 -> 0.58917366 | AT14: ='[1]209'!C17 -> 1.5964805 | AU14: ='[1]209'!B70 -> 0.28991143 | AV14: ='[1]209'!C70 -> 3.4839091 | AW14: ='[1]209'!B494 -> 0.50996004 | AX14: ='[1]209'!C494 -> 0.94968365 | AY14: ='[1]209'!B547 -> -16.857947 | AZ14: ='[1]209'!C547 -> -2.5560783 | BA14: ='[1]209'!B706 -> -7.0341102 | BB14: ='[1]209'!C706 -> 3.2279781 | BC14: - | BD14: - | BE14: - | BF14: - | BG14: ='[1]210'!B17 -> 4.9545249 | BH14: ='[1]210'!C17 -> 5.1797077 | BI14: ='[1]210'!B70 -> 5.361919 | BJ14: ='[1]210'!C70 -> 5.1315771 | BK14: ='[1]210'!B494 -> 3.4496836 | BL14: ='[1]210'!C494 -> 4.5823071 | BM14: ='[1]210'!B547 -> 9.752957 | BN14: ='[1]210'!C547 -> 5.1615507 | BO14: ='[1]210'!B706 -> 2.8927201 | BP14: ='[1]210'!C706 -> 5.4977712 | BQ14: - | BR14: - | BS14: - | BT14: - | BU14: ='[1]211'!B17 -> 4.9545249 | BV14: ='[1]211'!C17 -> 5.0678873 | BW14: ='[1]211'!B70 -> 5.361919 | BX14: ='[1]211'!C70 -> 5.2446501 | BY14: ='[1]211'!B494 -> 3.4496836 | BZ14: ='[1]211'!C494 -> 4.0155885 | CA14: ='[1]211'!B547 -> 9.752957 | CB14: ='[1]211'!C547 -> 7.4379232 | CC14: ='[1]211'!B706 -> 2.8927201 | CD14: ='[1]211'!C706 -> 4.1996526 | CE14: - | CF14: - | CG14: - | CH14: - | CI14: ='[1]212'!B17 -> 0.50295145 | CJ14: ='[1]212'!C17 -> 0.39526763 | CK14: ='[1]212'!B70 -> -0.011555002 | CL14: ='[1]212'!C70 -> 1.7504632 | CM14: ='[1]212'!B494 -> -0.69938922 | CN14: ='[1]212'!C494 -> 2.5623048 | CO14: ='[1]212'!B547 -> -4.1292651 | CP14: ='[1]212'!C547 -> 2.0722256 | CQ14: ='[1]212'!B706 -> 0.26513286 | CR14: ='[1]212'!C706 -> 0.14784223 | CS14: - | CT14: - | CU14: - | CV14: - | CW14: ='[1]213'!B17 -> 1.8149056 | CX14: ='[1]213'!C17 -> 1.3838662 | CY14: ='[1]213'!B70 -> 0.84568365 | CZ14: ='[1]213'!C70 -> 1.9449149 | DA14: ='[1]213'!B494 -> 0.18855555 | DB14: ='[1]213'!C494 -> 2.1164525 | DC14: ='[1]213'!B547 -> 1.0032163 | DD14: ='[1]213'!C547 -> 1.0739205 | DE14: ='[1]213'!B706 -> 0.90109918 | DF14: ='[1]213'!C706 -> 0.8665657 | DG14: - | DH14: - | DI14: - | DJ14: -
A15: 32 | B15: Jawa Barat | C15: ='[1]201'!B18 -> 7.3393861e+08 | D15: ='[1]201'!C18 -> 7.5518765e+08 | E15: ='[1]201'!B71 -> 4.8138277e+08 | F15: ='[1]201'!C71 -> 5.0268076e+08 | G15: ='[1]201'!B495 -> 4960597.3 | H15: ='[1]201'!C495 -> 5209412.8 | I15: ='[1]201'!B548 -> 26070615 | J15: ='[1]201'!C548 -> 32799808 | K15: ='[1]201'!B707 -> 1.7744875e+08 | L15: ='[1]201'!C707 -> 1.8310208e+08 | M15: ='[1]201'!B866 -> -276459.16 | N15: ='[1]201'!C866 -> 227366.59 | O15: =C15-(E15+G15+I15+K15+M15) -> 44352340 | P15: =D15-(F15+H15+J15+L15+N15) -> 31168220 | Q15: ='[1]202'!B18 -> 4.4931429e+08 | R15: ='[1]202'!C18 -> 4.5980497e+08 | S15: ='[1]202'!B71 -> 2.6861165e+08 | T15: ='[1]202'!C71 -> 2.7825963e+08 | U15: ='[1]202'!B495 -> 3038623.3 | V15: ='[1]202'!C495 -> 3099699.6 | W15: ='[1]202'!B548 -> 14611758 | X15: ='[1]202'!C548 -> 18205469 | Y15: ='[1]202'!B707 -> 1.0453564e+08 | Z15: ='[1]202'!C707 -> 1.0768991e+08 | AA15: ='[1]202'!B866 -> -143601.6 | AB15: ='[1]202'!C866 -> 116826.35 | AC15: =Q15-(S15+U15+W15+Y15+AA15) -> 58660216 | AD15: =R15-(T15+V15+X15+Z15+AB15) -> 52433441 | AE15: ='[1]205'!B18 -> 100 | AF15: ='[1]205'!C18 -> 100 | AG15: ='[1]205'!B71 -> 65.588969 | AH15: ='[1]205'!C71 -> 66.563689 | AI15: ='[1]205'!B495 -> 0.67588722 | AJ15: ='[1]205'!C495 -> 0.689817 | AK15: ='[1]205'!B548 -> 3.552152 | AL15: ='[1]205'!C548 -> 4.3432659 | AM15: ='[1]205'!B707 -> 24.177601 | AN15: ='[1]205'!C707 -> 24.245905 | AO15: ='[1]205'!B866 -> -0.037667886 | AP15: ='[1]205'!C866 -> 0.030107297 | AQ15: =AE15-(AG15+AI15+AK15+AM15+AO15) -> 6.0430586 | AR15: =AF15-(AH15+AJ15+AL15+AN15+AP15) -> 4.1272153 | AS15: ='[1]209'!B18 -> 0.27912987 | AT15: ='[1]209'!C18 -> 2.3348203 | AU15: ='[1]209'!B71 -> 0.31590316 | AV15: ='[1]209'!C71 -> 3.5917949 | AW15: ='[1]209'!B495 -> 2.4075743 | AX15: ='[1]209'!C495 -> 2.01 | AY15: ='[1]209'!B548 -> -43.214739 | AZ15: ='[1]209'!C548 -> 24.594653 | BA15: ='[1]209'!B707 -> -2.4886 | BB15: ='[1]209'!C707 -> 3.0174031 | BC15: - | BD15: - | BE15: - | BF15: - | BG15: ='[1]210'!B18 -> 4.9846801 | BH15: ='[1]210'!C18 -> 5.2307802 | BI15: ='[1]210'!B71 -> 5.0104831 | BJ15: ='[1]210'!C71 -> 4.7639612 | BK15: ='[1]210'!B495 -> 5.83 | BL15: ='[1]210'!C495 -> 6.7812098 | BM15: ='[1]210'!B548 -> 0.18197808 | BN15: ='[1]210'!C548 -> -2.0161724 | BO15: ='[1]210'!B707 -> 3.1152281 | BP15: ='[1]210'!C707 -> 6.7878177 | BQ15: - | BR15: - | BS15: - | BT15: - | BU15: ='[1]211'!B18 -> 4.9846801 | BV15: ='[1]211'!C18 -> 5.109006 | BW15: ='[1]211'!B71 -> 5.0104831 | BX15: ='[1]211'!C71 -> 4.8849028 | BY15: ='[1]211'!B495 -> 5.83 | BZ15: ='[1]211'!C495 -> 6.3082095 | CA15: ='[1]211'!B548 -> 0.18197808 | CB15: ='[1]211'!C548 -> -1.0494841 | CC15: ='[1]211'!B707 -> 3.1152281 | CD15: ='[1]211'!C707 -> 4.9466852 | CE15: - | CF15: - | CG15: - | CH15: - | CI15: ='[1]212'!B18 -> 0.99402948 | CJ15: ='[1]212'!C18 -> 0.54760031 | CK15: ='[1]212'!B71 -> 0.2693999 | CL15: ='[1]212'!C71 -> 0.80367394 | CM15: ='[1]212'!B495 -> -1.4038475 | CN15: ='[1]212'!C495 -> 2.9466105 | CO15: ='[1]212'!B548 -> 0.015169903 | CP15: ='[1]212'!C548 -> 0.97656865 | CQ15: ='[1]212'!B707 -> 0.42442303 | CR15: ='[1]212'!C707 -> 0.16355928 | CS15: - | CT15: - | CU15: - | CV15: - | CW15: ='[1]213'!B18 -> 2.2603782 | CX15: ='[1]213'!C18 -> 1.5736939 | CY15: ='[1]213'!B71 -> 1.1036662 | CZ15: ='[1]213'!C71 -> 1.4703565 | DA15: ='[1]213'!B495 -> -0.55482547 | DB15: ='[1]213'!C495 -> 1.7439178 | DC15: ='[1]213'!B548 -> 0.44273804 | DD15: ='[1]213'!C548 -> 0.40192024 | DE15: ='[1]213'!B707 -> 1.1004296 | DF15: ='[1]213'!C707 -> 0.87860353 | DG15: - | DH15: - | DI15: - | DJ15: -
A16: 33 | B16: Jawa Tengah | C16: ='[1]201'!B19 -> 4.7294989e+08 | D16: ='[1]201'!C19 -> 4.8326003e+08 | E16: ='[1]201'!B72 -> 2.8563572e+08 | F16: ='[1]201'!C72 -> 2.9750982e+08 | G16: ='[1]201'!B496 -> 6389814 | H16: ='[1]201'!C496 -> 6626006.3 | I16: ='[1]201'!B549 -> 20702020 | J16: ='[1]201'!C549 -> 28485398 | K16: ='[1]201'!B708 -> 1.3642012e+08 | L16: ='[1]201'!C708 -> 1.4522024e+08 | M16: ='[1]201'!B867 -> 3860772.5 | N16: ='[1]201'!C867 -> 4020049 | O16: =C16-(E16+G16+I16+K16+M16) -> 19941455 | P16: =D16-(F16+H16+J16+L16+N16) -> 1398519.6 | Q16: ='[1]202'!B19 -> 2.9819532e+08 | R16: ='[1]202'!C19 -> 3.0377885e+08 | S16: ='[1]202'!B72 -> 1.7515397e+08 | T16: ='[1]202'!C72 -> 1.8039636e+08 | U16: ='[1]202'!B496 -> 3427177.2 | V16: ='[1]202'!C496 -> 3491020.6 | W16: ='[1]202'!B549 -> 11742863 | X16: ='[1]202'!C549 -> 16029937 | Y16: ='[1]202'!B708 -> 82036665 | Z16: ='[1]202'!C708 -> 87157403 | AA16: ='[1]202'!B867 -> 2676706.7 | AB16: ='[1]202'!C867 -> 2738344.2 | AC16: =Q16-(S16+U16+W16+Y16+AA16) -> 23157943 | AD16: =R16-(T16+V16+X16+Z16+AB16) -> 13965793 | AE16: ='[1]205'!B19 -> 100 | AF16: ='[1]205'!C19 -> 100 | AG16: ='[1]205'!B72 -> 60.394499 | AH16: ='[1]205'!C72 -> 61.563092 | AI16: ='[1]205'!B496 -> 1.3510552 | AJ16: ='[1]205'!C496 -> 1.3711058 | AK16: ='[1]205'!B549 -> 4.3772121 | AL16: ='[1]205'!C549 -> 5.8944246 | AM16: ='[1]205'!B708 -> 28.844518 | AN16: ='[1]205'!C708 -> 30.050124 | AO16: ='[1]205'!B867 -> 0.81631744 | AP16: ='[1]205'!C867 -> 0.83186044 | AQ16: =AE16-(AG16+AI16+AK16+AM16+AO16) -> 4.216399 | AR16: =AF16-(AH16+AJ16+AL16+AN16+AP16) -> 0.28939277 | AS16: ='[1]209'!B19 -> 1.8073914 | AT16: ='[1]209'!C19 -> 1.8724411 | AU16: ='[1]209'!B72 -> 0.68034363 | AV16: ='[1]209'!C72 -> 2.993018 | AW16: ='[1]209'!B496 -> 0.75956376 | AX16: ='[1]209'!C496 -> 1.8628567 | AY16: ='[1]209'!B549 -> -47.143353 | AZ16: ='[1]209'!C549 -> 36.507907 | BA16: ='[1]209'!B708 -> -9.6486189 | BB16: ='[1]209'!C708 -> 6.2420113 | BC16: - | BD16: - | BE16: - | BF16: - | BG16: ='[1]210'!B19 -> 4.9697127 | BH16: ='[1]210'!C19 -> 5.2832694 | BI16: ='[1]210'!B72 -> 4.9832302 | BJ16: ='[1]210'!C72 -> 4.7639628 | BK16: ='[1]210'!B496 -> 1.4825794 | BL16: ='[1]210'!C496 -> 3.2624277 | BM16: ='[1]210'!B549 -> -1.0399075 | BN16: ='[1]210'!C549 -> -2.7371468 | BO16: ='[1]210'!B708 -> 4.5544945 | BP16: ='[1]210'!C708 -> 8.6490002 | BQ16: - | BR16: - | BS16: - | BT16: - | BU16: ='[1]211'!B19 -> 4.9697127 | BV16: ='[1]211'!C19 -> 5.1277114 | BW16: ='[1]211'!B72 -> 4.9832302 | BX16: ='[1]211'!C72 -> 4.8718655 | BY16: ='[1]211'!B496 -> 1.4825794 | BZ16: ='[1]211'!C496 -> 2.37298 | CA16: ='[1]211'!B549 -> -1.0399075 | CB16: ='[1]211'!C549 -> -2.0266778 | CC16: ='[1]211'!B708 -> 4.5544945 | CD16: ='[1]211'!C708 -> 6.6244047 | CE16: - | CF16: - | CG16: - | CH16: - | CI16: ='[1]212'!B19 -> 0.79547334 | CJ16: ='[1]212'!C19 -> 0.30187106 | CK16: ='[1]212'!B72 -> -0.10204947 | CL16: ='[1]212'!C72 -> 1.130233 | CM16: ='[1]212'!B496 -> -0.04011636 | CN16: ='[1]212'!C496 -> 1.8000009 | CO16: ='[1]212'!B549 -> 1.941038 | CP16: ='[1]212'!C549 -> 0.79796507 | CQ16: ='[1]212'!B708 -> 0.20948302 | CR16: ='[1]212'!C708 -> 0.19647787 | CS16: - | CT16: - | CU16: - | CV16: - | CW16: ='[1]213'!B19 -> 1.2827322 | CX16: ='[1]213'!C19 -> 1.2589802 | CY16: ='[1]213'!B72 -> 0.80329806 | CZ16: ='[1]213'!C72 -> 1.5028532 | DA16: ='[1]213'!B496 -> 0.23344944 | DB16: ='[1]213'!C496 -> 1.9980021 | DC16: ='[1]213'!B549 -> 1.1677553 | DD16: ='[1]213'!C549 -> 0.72535312 | DE16: ='[1]213'!B708 -> 1.9923168 | DF16: ='[1]213'!C708 -> 1.0754313 | DG16: - | DH16: - | DI16: - | DJ16: -
A17: 34 | B17: Di Yogyakarta | C17: ='[1]201'!B20 -> 50945360 | D17: ='[1]201'!C20 -> 51763128 | E17: ='[1]201'!B73 -> 31192896 | F17: ='[1]201'!C73 -> 32224888 | G17: ='[1]201'!B497 -> 1627811.6 | H17: ='[1]201'!C497 -> 1644519.9 | I17: ='[1]201'!B550 -> 6551785.6 | J17: ='[1]201'!C550 -> 6989000.5 | K17: ='[1]201'!B709 -> 16583457 | L17: ='[1]201'!C709 -> 17900530 | M17: ='[1]201'!B868 -> 668104.73 | N17: ='[1]201'!C868 -> 1035918.2 | O17: =C17-(E17+G17+I17+K17+M17) -> -5678695.1 | P17: =D17-(F17+H17+J17+L17+N17) -> -8031728.5 | Q17: ='[1]202'!B20 -> 32249180 | R17: ='[1]202'!C20 -> 32636417 | S17: ='[1]202'!B73 -> 17108111 | T17: ='[1]202'!C73 -> 17527967 | U17: ='[1]202'!B497 -> 887034.74 | V17: ='[1]202'!C497 -> 894463.39 | W17: ='[1]202'!B550 -> 3487626.2 | X17: ='[1]202'!C550 -> 3691659 | Y17: ='[1]202'!B709 -> 8346904.4 | Z17: ='[1]202'!C709 -> 8992056.9 | AA17: ='[1]202'!B868 -> 429724.78 | AB17: ='[1]202'!C868 -> 665409.02 | AC17: =Q17-(S17+U17+W17+Y17+AA17) -> 1989778.5 | AD17: =R17-(T17+V17+X17+Z17+AB17) -> 864861.6 | AE17: ='[1]205'!B20 -> 100 | AF17: ='[1]205'!C20 -> 100 | AG17: ='[1]205'!B73 -> 61.22814 | AH17: ='[1]205'!C73 -> 62.254522 | AI17: ='[1]205'!B497 -> 3.1952108 | AJ17: ='[1]205'!C497 -> 3.1770103 | AK17: ='[1]205'!B550 -> 12.860417 | AL17: ='[1]205'!C550 -> 13.50189 | AM17: ='[1]205'!B709 -> 32.551456 | AN17: ='[1]205'!C709 -> 34.581624 | AO17: ='[1]205'!B868 -> 1.3114143 | AP17: ='[1]205'!C868 -> 2.0012667 | AQ17: =AE17-(AG17+AI17+AK17+AM17+AO17) -> -11.146638 | AR17: =AF17-(AH17+AJ17+AL17+AN17+AP17) -> -15.516312 | AS17: ='[1]209'!B20 -> 0.96991442 | AT17: ='[1]209'!C20 -> 1.2007654 | AU17: ='[1]209'!B73 -> 0.68592213 | AV17: ='[1]209'!C73 -> 2.454132 | AW17: ='[1]209'!B497 -> 0.6307189 | AX17: ='[1]209'!C497 -> 0.83747065 | AY17: ='[1]209'!B550 -> -24.67747 | AZ17: ='[1]209'!C550 -> 5.8501926 | BA17: ='[1]209'!B709 -> -8.558475 | BB17: ='[1]209'!C709 -> 7.7292431 | BC17: - | BD17: - | BE17: - | BF17: - | BG17: ='[1]210'!B20 -> 5.1122338 | BH17: ='[1]210'!C20 -> 5.4928891 | BI17: ='[1]210'!B73 -> 4.8019803 | BJ17: ='[1]210'!C73 -> 4.4301306 | BK17: ='[1]210'!B497 -> -1.465072 | BL17: ='[1]210'!C497 -> 4.1332315 | BM17: ='[1]210'!B550 -> 2.2583102 | BN17: ='[1]210'!C550 -> 2.0047982 | BO17: ='[1]210'!B709 -> 4.5757653 | BP17: ='[1]210'!C709 -> 8.2261198 | BQ17: - | BR17: - | BS17: - | BT17: - | BU17: ='[1]211'!B20 -> 5.1122338 | BV17: ='[1]211'!C20 -> 5.3033533 | BW17: ='[1]211'!B73 -> 4.8019803 | BX17: ='[1]211'!C73 -> 4.6134713 | BY17: ='[1]211'!B497 -> -1.465072 | BZ17: ='[1]211'!C497 -> 1.2684234 | CA17: ='[1]211'!B550 -> 2.2583102 | CB17: ='[1]211'!C550 -> 2.1277946 | CC17: ='[1]211'!B709 -> 4.5757653 | CD17: ='[1]211'!C709 -> 6.437569 | CE17: - | CF17: - | CG17: - | CH17: - | CI17: ='[1]212'!B20 -> 1.4248926 | CJ17: ='[1]212'!C20 -> 0.39962231 | CK17: ='[1]212'!B73 -> 0.55825716 | CL17: ='[1]212'!C73 -> 0.83382234 | CM17: ='[1]212'!B497 -> 0.36748999 | CN17: ='[1]212'!C497 -> 0.18738605 | CO17: ='[1]212'!B550 -> -0.40408156 | CP17: ='[1]212'!C550 -> 0.77753768 | CQ17: ='[1]212'!B709 -> 1.2305475 | CR17: ='[1]212'!C709 -> 0.19757808 | CS17: - | CT17: - | CU17: - | CV17: - | CW17: ='[1]213'!B20 -> 1.8716941 | CX17: ='[1]213'!C20 -> 2.0645462 | CY17: ='[1]213'!B73 -> 1.8493575 | CZ17: ='[1]213'!C73 -> 2.6980012 | DA17: ='[1]213'!B497 -> 1.7979168 | DB17: ='[1]213'!C497 -> 1.0906139 | DC17: ='[1]213'!B550 -> 2.2696957 | DD17: ='[1]213'!C550 -> 2.2395582 | DE17: ='[1]213'!B709 -> 3.022766 | DF17: ='[1]213'!C709 -> 2.4928467 | DG17: - | DH17: - | DI17: - | DJ17: -
A18: 35 | B18: Jawa Timur | C18: ='[1]201'!B21 -> 8.1929946e+08 | D18: ='[1]201'!C21 -> 8.492992e+08 | E18: ='[1]201'!B74 -> 4.992802e+08 | F18: ='[1]201'!C74 -> 5.1790845e+08 | G18: ='[1]201'!B498 -> 10742342 | H18: ='[1]201'!C498 -> 10802427 | I18: ='[1]201'!B551 -> 25863143 | J18: ='[1]201'!C551 -> 31091359 | K18: ='[1]201'!B710 -> 2.1427808e+08 | L18: ='[1]201'!C710 -> 2.2582924e+08 | M18: ='[1]201'!B869 -> 4879456.1 | N18: ='[1]201'!C869 -> 7318291.2 | O18: =C18-(E18+G18+I18+K18+M18) -> 64256244 | P18: =D18-(F18+H18+J18+L18+N18) -> 56349433 | Q18: ='[1]202'!B21 -> 4.9418772e+08 | R18: ='[1]202'!C21 -> 5.0945391e+08 | S18: ='[1]202'!B74 -> 2.9645914e+08 | T18: ='[1]202'!C74 -> 3.0488557e+08 | U18: ='[1]202'!B498 -> 5829272.4 | V18: ='[1]202'!C498 -> 5835036.2 | W18: ='[1]202'!B551 -> 16479596 | X18: ='[1]202'!C551 -> 19185345 | Y18: ='[1]202'!B710 -> 1.2636562e+08 | Z18: ='[1]202'!C710 -> 1.3264522e+08 | AA18: ='[1]202'!B869 -> 2648500.8 | AB18: ='[1]202'!C869 -> 3958084.4 | AC18: =Q18-(S18+U18+W18+Y18+AA18) -> 46405593 | AD18: =R18-(T18+V18+X18+Z18+AB18) -> 42944651 | AE18: ='[1]205'!B21 -> 100 | AF18: ='[1]205'!C21 -> 100 | AG18: ='[1]205'!B74 -> 60.939891 | AH18: ='[1]205'!C74 -> 60.980683 | AI18: ='[1]205'!B498 -> 1.3111618 | AJ18: ='[1]205'!C498 -> 1.2719225 | AK18: ='[1]205'!B551 -> 3.1567387 | AL18: ='[1]205'!C551 -> 3.6608252 | AM18: ='[1]205'!B710 -> 26.153817 | AN18: ='[1]205'!C710 -> 26.590068 | AO18: ='[1]205'!B869 -> 0.59556442 | AP18: ='[1]205'!C869 -> 0.86168586 | AQ18: =AE18-(AG18+AI18+AK18+AM18+AO18) -> 7.8428276 | AR18: =AF18-(AH18+AJ18+AL18+AN18+AP18) -> 6.6348152 | AS18: ='[1]209'!B21 -> 1.1365497 | AT18: ='[1]209'!C21 -> 3.0891477 | AU18: ='[1]209'!B74 -> 0.7737266 | AV18: ='[1]209'!C74 -> 2.8423579 | AW18: ='[1]209'!B498 -> -0.96440125 | AX18: ='[1]209'!C498 -> 0.098876834 | AY18: ='[1]209'!B551 -> -23.837107 | AZ18: ='[1]209'!C551 -> 16.418784 | BA18: ='[1]209'!B710 -> -6.4026801 | BB18: ='[1]209'!C710 -> 4.9693928 | BC18: - | BD18: - | BE18: - | BF18: - | BG18: ='[1]210'!B21 -> 5.0048659 | BH18: ='[1]210'!C21 -> 5.234076 | BI18: ='[1]210'!B74 -> 5.116112 | BJ18: ='[1]210'!C74 -> 4.8507301 | BK18: ='[1]210'!B498 -> 6.5295368 | BL18: ='[1]210'!C498 -> 6.4185699 | BM18: ='[1]210'!B551 -> 1.9246334 | BN18: ='[1]210'!C551 -> -0.54904388 | BO18: ='[1]210'!B710 -> 2.203234 | BP18: ='[1]210'!C710 -> 6.1299783 | BQ18: - | BR18: - | BS18: - | BT18: - | BU18: ='[1]211'!B21 -> 5.0048659 | BV18: ='[1]211'!C21 -> 5.1210893 | BW18: ='[1]211'!B74 -> 5.116112 | BX18: ='[1]211'!C74 -> 4.981394 | BY18: ='[1]211'!B498 -> 6.5295368 | BZ18: ='[1]211'!C498 -> 6.4739971 | CA18: ='[1]211'!B551 -> 1.9246334 | CB18: ='[1]211'!C551 -> 0.57886932 | CC18: ='[1]211'!B710 -> 2.203234 | CD18: ='[1]211'!C710 -> 4.1772057 | CE18: - | CF18: - | CG18: - | CH18: - | CI18: ='[1]212'!B21 -> 0.95289576 | CJ18: ='[1]212'!C21 -> 0.55533057 | CK18: ='[1]212'!B74 -> 0.64338274 | CL18: ='[1]212'!C74 -> 0.86410359 | CM18: ='[1]212'!B498 -> 0.39389792 | CN18: ='[1]212'!C498 -> 0.46000364 | CO18: ='[1]212'!B551 -> -11.318409 | CP18: ='[1]212'!C551 -> 3.260766 | CQ18: ='[1]212'!B710 -> 0.55556289 | CR18: ='[1]212'!C710 -> 0.40139369 | CS18: - | CT18: - | CU18: - | CV18: - | CW18: ='[1]213'!B21 -> 2.0868864 | CX18: ='[1]213'!C21 -> 1.769567 | CY18: ='[1]213'!B74 -> 1.2885954 | CZ18: ='[1]213'!C74 -> 1.473575 | DA18: ='[1]213'!B498 -> 1.2764362 | DB18: ='[1]213'!C498 -> 1.1954564 | DC18: ='[1]213'!B551 -> 10.268361 | DD18: ='[1]213'!C551 -> 2.9201597 | DE18: ='[1]213'!B710 -> 1.9743118 | DF18: ='[1]213'!C710 -> 2.2105733 | DG18: - | DH18: - | DI18: - | DJ18: -
A19: 36 | B19: Banten | C19: ='[1]201'!B22 -> 2.2791701e+08 | D19: ='[1]201'!C22 -> 2.322301e+08 | E19: ='[1]201'!B75 -> 1.2049909e+08 | F19: ='[1]201'!C75 -> 1.229831e+08 | G19: ='[1]201'!B499 -> 1031443.2 | H19: ='[1]201'!C499 -> 1071704.7 | I19: ='[1]201'!B552 -> 8477630.4 | J19: ='[1]201'!C552 -> 9442989.2 | K19: ='[1]201'!B711 -> 76297400 | L19: ='[1]201'!C711 -> 82102753 | M19: ='[1]201'!B870 -> 42412.522 | N19: ='[1]201'!C870 -> 69240.457 | O19: =C19-(E19+G19+I19+K19+M19) -> 21569035 | P19: =D19-(F19+H19+J19+L19+N19) -> 16560304 | Q19: ='[1]202'!B22 -> 1.3722103e+08 | R19: ='[1]202'!C22 -> 1.3912436e+08 | S19: ='[1]202'!B75 -> 75707932 | T19: ='[1]202'!C75 -> 76877101 | U19: ='[1]202'!B499 -> 625609.57 | V19: ='[1]202'!C499 -> 648997.55 | W19: ='[1]202'!B552 -> 4228298.8 | X19: ='[1]202'!C552 -> 4614868.5 | Y19: ='[1]202'!B711 -> 41536829 | Z19: ='[1]202'!C711 -> 44337916 | AA19: ='[1]202'!B870 -> 27859.523 | AB19: ='[1]202'!C870 -> 44540.811 | AC19: =Q19-(S19+U19+W19+Y19+AA19) -> 15094503 | AD19: =R19-(T19+V19+X19+Z19+AB19) -> 12600934 | AE19: ='[1]205'!B22 -> 100 | AF19: ='[1]205'!C22 -> 100 | AG19: ='[1]205'!B75 -> 52.869723 | AH19: ='[1]205'!C75 -> 52.957436 | AI19: ='[1]205'!B499 -> 0.45255207 | AJ19: ='[1]205'!C499 -> 0.46148399 | AK19: ='[1]205'!B552 -> 3.7196128 | AL19: ='[1]205'!C552 -> 4.0662211 | AM19: ='[1]205'!B711 -> 33.475956 | AN19: ='[1]205'!C711 -> 35.354054 | AO19: ='[1]205'!B870 -> 0.018608756 | AP19: ='[1]205'!C870 -> 0.029815454 | AQ19: =AE19-(AG19+AI19+AK19+AM19+AO19) -> 9.4635477 | AR19: =AF19-(AH19+AJ19+AL19+AN19+AP19) -> 7.1309895 | AS19: ='[1]209'!B22 -> 1.0076956 | AT19: ='[1]209'!C22 -> 1.3870515 | AU19: ='[1]209'!B75 -> 0.77344706 | AV19: ='[1]209'!C75 -> 1.5443158 | AW19: ='[1]209'!B499 -> 1.0647469 | AX19: ='[1]209'!C499 -> 3.73843 | AY19: ='[1]209'!B552 -> -24.691209 | AZ19: ='[1]209'!C552 -> 9.1424412 | BA19: ='[1]209'!B711 -> -1.7953288 | BB19: ='[1]209'!C711 -> 6.7436212 | BC19: - | BD19: - | BE19: - | BF19: - | BG19: ='[1]210'!B22 -> 5.1928263 | BH19: ='[1]210'!C22 -> 5.3324183 | BI19: ='[1]210'!B75 -> 5.483946 | BJ19: ='[1]210'!C75 -> 3.6115112 | BK19: ='[1]210'!B499 -> -2.2839304 | BL19: ='[1]210'!C499 -> 1.3050266 | BM19: ='[1]210'!B552 -> -0.36818561 | BN19: ='[1]210'!C552 -> -0.41938375 | BO19: ='[1]210'!B711 -> 1.8228863 | BP19: ='[1]210'!C711 -> 9.9014547 | BQ19: - | BR19: - | BS19: - | BT19: - | BU19: ='[1]211'!B22 -> 5.1928263 | BV19: ='[1]211'!C22 -> 5.2630568 | BW19: ='[1]211'!B75 -> 5.483946 | BX19: ='[1]211'!C75 -> 4.5321722 | BY19: ='[1]211'!B499 -> -2.2839304 | BZ19: ='[1]211'!C499 -> -0.48888447 | CA19: ='[1]211'!B552 -> -0.36818561 | CB19: ='[1]211'!C552 -> -0.39491029 | CC19: ='[1]211'!B711 -> 1.8228863 | CD19: ='[1]211'!C711 -> 5.8397739 | CE19: - | CF19: - | CG19: - | CH19: - | CI19: ='[1]212'!B22 -> 0.31415063 | CJ19: ='[1]212'!C22 -> 0.49842618 | CK19: ='[1]212'!B75 -> -0.35172775 | CL19: ='[1]212'!C75 -> 0.50925559 | CM19: ='[1]212'!B499 -> -0.13173658 | CN19: ='[1]212'!C499 -> 0.15904399 | CO19: ='[1]212'!B552 -> -0.51376526 | CP19: ='[1]212'!C552 -> 2.0566602 | CQ19: ='[1]212'!B711 -> 1.2997997 | CR19: ='[1]212'!C711 -> 0.81056525 | CS19: - | CT19: - | CU19: - | CV19: - | CW19: ='[1]213'!B22 -> 2.3358063 | CX19: ='[1]213'!C22 -> 1.5588099 | CY19: ='[1]213'!B75 -> 3.4072493 | CZ19: ='[1]213'!C75 -> 2.1354738 | DA19: ='[1]213'!B499 -> 2.5777457 | DB19: ='[1]213'!C499 -> 1.1643563 | DC19: ='[1]213'!B552 -> 4.0900583 | DD19: ='[1]213'!C552 -> 4.3082244 | DE19: ='[1]213'!B711 -> 3.3209023 | DF19: ='[1]213'!C711 -> 3.645751 | DG19: - | DH19: - | DI19: - | DJ19: -
